<robot name="carter">

  <!-- the model -->
  <link name="base_link">
    <visual>
      <origin rpy="0 0 0" xyz="0 0 0"/>
      <geometry>
        <mesh filename="file:/home/andrea/catkin_ws/src/carter/carter_description/meshes/low/base.stl" scale="0.001 0.001 0.001"/>
      </geometry>
      <material name="Cyan">
        <color rgba="0 1.0 1.0 1.0"/>
      </material>
    </visual>
  </link>

  <link name="wheel_r">
    <visual>
      <origin rpy="0 0 0" xyz="0 0 0"/>
      <geometry>
        <mesh filename="file:/home/andrea/catkin_ws/src/carter/carter_description/meshes/wheel_r.stl" scale="0.001 0.001 0.001"/>
      </geometry>
      <material name="Cyan">
        <color rgba="0 1.0 1.0 1.0"/>
      </material>
    </visual>
  </link>

  <link name="wheel_l">
    <visual>
      <origin rpy="0 0 0" xyz="0 0 0"/>
      <geometry>
        <mesh filename="file:/home/andrea/catkin_ws/src/carter/carter_description/meshes/wheel_l.stl" scale="0.001 0.001 0.001"/>
      </geometry>
      <material name="Cyan">
        <color rgba="0 1.0 1.0 1.0"/>
      </material>
    </visual>
  </link>

  <joint name="wheel_r_joint" type="continuous">
    <parent link="base_link"/>
    <child link="wheel_r"/>
    <origin xyz="0.1242 -0.000183 0.009979" rpy="0 0 0" />
    <axis xyz="1 0 0" />
  </joint>

  <joint name="wheel_l_joint" type="continuous">
    <parent link="base_link"/>
    <child link="wheel_l"/>
    <origin xyz="0 0 0" rpy="0 0 0" />
    <axis xyz="1 0 0" />
  </joint>

</robot>